Workbook
Name GlobalRate: 0.125
Name Numbers: Inputs!$A$1:$A$8
Name Rate: 0.2
Name Rate: 0.1

Sheet Inputs
A1: 2 | B1: TRUE | C1: apple | D1: red | E1: 1 | F1: 59
A2: 4 | B2: FALSE | C2: apricot | D2: red | E2: 2 | F2: 60
A3: 4 | B3: 3 | C3: a*b | D3: blue | E3: 3 | F3: 61
A4: 8 | B4: x | C4: A?b | D4: red | E4: 4 | F4: 0.12345679
A5: 10 | C5: berry | D5: blue | E5: 5 | F5: 45292.123
A6: 12 | B6: 0 | C6: alpha | D6: red | E6: 6
A7: 14 | B7: ="" | C7: ~ | D7: blue | E7: 7
A8: 16 | B8: 5 | D8: red | E8: 8

Sheet Lookup
A1: 1 | B1: one | D1: 9
A2: 3 | B2: three | D2: 5
A3: 5 | B3: five | D3: 3
A4: 9 | B4: nine | D4: 1
A6: 1 | B6: 3 | C6: 5 | D6: 9
A7: 10 | B7: 30 | C7: 50 | D7: 90

Sheet Matrix
A1: 1 | B1: 2 | C1: 3
A2: 4 | B2: 5 | C2: 6
A3: 7 | B3: 8 | C3: 9

Sheet Hidden
A1: 1 | B1: 10
A2: 2 | B2: 20
A3: 3
A4: 4
A5: 5
A6: =SUBTOTAL(9,B1:B2) -> 30
A7: text

Sheet Flows
A1: -1000
A2: 300
A3: 400
A4: 500

Sheet Errors
A1: #NULL!
A2: #DIV/0!
A3: #VALUE!
A4: #REF!
A5: #NAME?
A6: #NUM!
A7: #N/A
A8: #N/A

Sheet Stability
A1: 100000000001
A2: 100000000002
A3: 100000000003
A4: 100000000004

Sheet Jan
A1: 10

Sheet Feb
A1: 20

Sheet Mar
A1: 30

Sheet Cases
A1: Case ID | B1: Native formula result | C1: Mode | D1: Original formula
A2: function-abs | B2: =ABS(-7.25) -> 7.25 | C2: cached_equal | D2: ABS(-7.25)
A3: function-acos | B3: =ACOS(0.25) -> 1.3181161 | C3: cached_equal | D3: ACOS(0.25)
A4: function-asin | B4: =ASIN(-0.25) -> -0.25268026 | C4: cached_equal | D4: ASIN(-0.25)
A5: function-atan | B5: =ATAN(2) -> 1.1071487 | C5: cached_equal | D5: ATAN(2)
A6: function-atan2 | B6: =ATAN2(-3,4) -> 2.2142974 | C6: cached_equal | D6: ATAN2(-3,4)
A7: function-ceiling | B7: =CEILING(4.3,0.5) -> 4.5 | C7: cached_equal | D7: CEILING(4.3,0.5)
A8: function-ceiling-math | B8: =_xlfn.CEILING.MATH(-4.3,2,1) -> -6 | C8: cached_equal | D8: CEILING.MATH(-4.3,2,1)
A9: function-cos | B9: =COS(0.75) -> 0.73168887 | C9: cached_equal | D9: COS(0.75)
A10: function-degrees | B10: =DEGREES(1.25) -> 71.619724 | C10: cached_equal | D10: DEGREES(1.25)
A11: function-even | B11: =EVEN(-3.2) -> -4 | C11: cached_equal | D11: EVEN(-3.2)
A12: function-exp | B12: =EXP(1.5) -> 4.4816891 | C12: cached_equal | D12: EXP(1.5)
A13: function-fact | B13: =FACT(7) -> 5040 | C13: cached_equal | D13: FACT(7)
A14: function-floor | B14: =FLOOR(4.7,0.5) -> 4.5 | C14: cached_equal | D14: FLOOR(4.7,0.5)
A15: function-floor-math | B15: =_xlfn.FLOOR.MATH(-4.3,2,1) -> -4 | C15: cached_equal | D15: FLOOR.MATH(-4.3,2,1)
A16: function-gcd | B16: =GCD(24,36,54) -> 6 | C16: cached_equal | D16: GCD(24,36,54)
A17: function-int | B17: =INT(-3.2) -> -4 | C17: cached_equal | D17: INT(-3.2)
A18: function-lcm | B18: =LCM(6,8,9) -> 72 | C18: cached_equal | D18: LCM(6,8,9)
A19: function-ln | B19: =LN(2.5) -> 0.91629073 | C19: cached_equal | D19: LN(2.5)
A20: function-log | B20: =LOG(125,5) -> 3 | C20: cached_equal | D20: LOG(125,5)
A21: function-log10 | B21: =LOG10(1000) -> 3 | C21: cached_equal | D21: LOG10(1000)
A22: function-mod | B22: =MOD(-7,3) -> 2 | C22: cached_equal | D22: MOD(-7,3)
A23: function-mround | B23: =MROUND(10,3) -> 9 | C23: cached_equal | D23: MROUND(10,3)
A24: function-odd | B24: =ODD(-2.1) -> -3 | C24: cached_equal | D24: ODD(-2.1)
A25: function-pi | B25: =PI() -> 3.1415927 | C25: cached_equal | D25: PI()
A26: function-power | B26: =POWER(2.5,3) -> 15.625 | C26: cached_equal | D26: POWER(2.5,3)
A27: function-product | B27: =PRODUCT(Inputs!A1:A4) -> 256 | C27: cached_equal | D27: PRODUCT(Inputs!A1:A4)
A28: function-quotient | B28: =QUOTIENT(-7,3) -> -2 | C28: cached_equal | D28: QUOTIENT(-7,3)
A29: function-radians | B29: =RADIANS(135) -> 2.3561945 | C29: cached_equal | D29: RADIANS(135)
A30: function-rand | B30: =RAND() -> 0.54258762 | C30: behavior_only | D30: RAND()
A31: function-randbetween | B31: =RANDBETWEEN(-5,7) -> 7 | C31: behavior_only | D31: RANDBETWEEN(-5,7)
A32: function-round | B32: =ROUND(2.675,2) -> 2.68 | C32: cached_equal | D32: ROUND(2.675,2)
A33: function-rounddown | B33: =ROUNDDOWN(-3.14159,3) -> -3.141 | C33: cached_equal | D33: ROUNDDOWN(-3.14159,3)
A34: function-roundup | B34: =ROUNDUP(-3.14159,3) -> -3.142 | C34: cached_equal | D34: ROUNDUP(-3.14159,3)
A35: function-sign | B35: =SIGN(-0.001) -> -1 | C35: cached_equal | D35: SIGN(-0.001)
A36: function-sin | B36: =SIN(0.75) -> 0.68163876 | C36: cached_equal | D36: SIN(0.75)
A37: function-sqrt | B37: =SQRT(2) -> 1.4142136 | C37: cached_equal | D37: SQRT(2)
A38: function-subtotal | B38: =SUBTOTAL(9,Hidden!A1:A8) -> 15 | C38: cached_equal | D38: SUBTOTAL(9,Hidden!A1:A8)
A39: function-sum | B39: =SUM(Inputs!A1:A8) -> 70 | C39: cached_equal | D39: SUM(Inputs!A1:A8)
A40: function-sumif | B40: =SUMIF(Inputs!C1:C8,"a*",Inputs!A1:A8) -> 30 | C40: cached_equal | D40: SUMIF(Inputs!C1:C8,"a*",Inputs!A1:A8)
...

Sheet Scoped
A1: Case ID | B1: Native formula result | C1: Mode | D1: Original formula
A2: name-local | B2: =Rate*100 -> 20 | C2: cached_equal | D2: Rate*100
